telegram.ext.dispatcher -ERROR-An uncaught error was raised while processing the update
Traceback (most recent call last):
  File "C:\Users\User\AppData\Local\Programs\Python\Python36-32\lib\site-packages\telegram\ext\dispatcher.py", line 270, in process_update
    handler.handle_update(update, self)
  File "C:\Users\User\AppData\Local\Programs\Python\Python36-32\lib\site-packages\telegram\ext\commandhandler.py", line 171, in handle_update
    return self.callback(dispatcher.bot, update, **optional_args)
  File "bot.py", line 11, in greet_user
    print (1/0)
ZeroDivisionError: division by zero
telegram.ext.dispatcher -ERROR-An uncaught error was raised while processing the update
Traceback (most recent call last):
  File "C:\Users\User\AppData\Local\Programs\Python\Python36-32\lib\site-packages\telegram\ext\dispatcher.py", line 270, in process_update
    handler.handle_update(update, self)
  File "C:\Users\User\AppData\Local\Programs\Python\Python36-32\lib\site-packages\telegram\ext\commandhandler.py", line 171, in handle_update
    return self.callback(dispatcher.bot, update, **optional_args)
  File "bot.py", line 11, in greet_user
    print (1/0)
ZeroDivisionError: division by zero
telegram.ext.dispatcher -ERROR-An uncaught error was raised while processing the update
Traceback (most recent call last):
  File "C:\Users\User\AppData\Local\Programs\Python\Python36-32\lib\site-packages\telegram\ext\dispatcher.py", line 270, in process_update
    handler.handle_update(update, self)
  File "C:\Users\User\AppData\Local\Programs\Python\Python36-32\lib\site-packages\telegram\ext\commandhandler.py", line 171, in handle_update
    return self.callback(dispatcher.bot, update, **optional_args)
  File "bot.py", line 11, in greet_user
    print (1/0)
ZeroDivisionError: division by zero
telegram.ext.dispatcher -ERROR-An uncaught error was raised while processing the update
Traceback (most recent call last):
  File "C:\Users\User\AppData\Local\Programs\Python\Python36-32\lib\site-packages\telegram\ext\dispatcher.py", line 270, in process_update
    handler.handle_update(update, self)
  File "C:\Users\User\AppData\Local\Programs\Python\Python36-32\lib\site-packages\telegram\ext\commandhandler.py", line 171, in handle_update
    return self.callback(dispatcher.bot, update, **optional_args)
  File "bot.py", line 11, in greet_user
    print (1/0)
ZeroDivisionError: division by zero
telegram.ext.dispatcher -ERROR-An uncaught error was raised while processing the update
Traceback (most recent call last):
  File "C:\Users\User\AppData\Local\Programs\Python\Python36-32\lib\site-packages\telegram\ext\dispatcher.py", line 270, in process_update
    handler.handle_update(update, self)
  File "C:\Users\User\AppData\Local\Programs\Python\Python36-32\lib\site-packages\telegram\ext\messagehandler.py", line 169, in handle_update
    return self.callback(dispatcher.bot, update, **optional_args)
  File "bot.py", line 19, in talk_to_me
    log.info(user_text)
NameError: name 'log' is not defined
telegram.ext.dispatcher -ERROR-An uncaught error was raised while processing the update
Traceback (most recent call last):
  File "C:\Users\User\AppData\Local\Programs\Python\Python36-32\lib\site-packages\telegram\ext\dispatcher.py", line 270, in process_update
    handler.handle_update(update, self)
  File "C:\Users\User\AppData\Local\Programs\Python\Python36-32\lib\site-packages\telegram\ext\messagehandler.py", line 169, in handle_update
    return self.callback(dispatcher.bot, update, **optional_args)
  File "bot.py", line 19, in talk_to_me
    log.info(user_text)
NameError: name 'log' is not defined
root -INFO-привет
root -INFO-как дела
